<?xml version="1.0" ?>
<robot xmlns:xacro="http://wiki.ros.org/xacro">
<xacro:macro name="robot">
<link name="base_link">
  <inertial>
    <origin rpy="0 0 0" xyz="0.198887 -0.80113 0.021369"/>
    <mass value="204.473744"/>
    <inertia ixx="6.821919" ixy="0.014918" ixz="4.362239" iyy="13.382202" iyz="-4.356184" izz="7.679036"/>
  </inertial>
  <visual>
    <origin rpy="0 0 0" xyz="0 0 0"/>
    <geometry>
      <mesh filename="package://myworkcell_support/urdf/mm_stl/base_link.stl" scale="0.001 0.001 0.001"/>
    </geometry>
    <material name="silver">
      <color rgba="1 0 0 1"/>
    </material>
  </visual>
  <collision>
    <origin rpy="0 0 0" xyz="0 0 0"/>
    <geometry>
      <mesh filename="package://myworkcell_support/urdf/mm_stl/base_link.stl" scale="0.001 0.001 0.001"/>
    </geometry>
  </collision>
</link>
<link name="Component2_1">
  <inertial>
    <origin rpy="0 0 0" xyz="0.025879999999999986 0.226487 0.0"/>
    <mass value="13.1521"/>
    <inertia ixx="0.660052" ixy="0.053525" ixz="1e-06" iyy="0.032176" iyz="-0.0" izz="0.673206"/>
  </inertial>
  <visual>
    <origin rpy="0 0 0" xyz="-0.24741 0.540257 -0.0"/>
    <geometry>
      <mesh filename="package://myworkcell_support/urdf/mm_stl/Component2_1.stl" scale="0.001 0.001 0.001"/>
    </geometry>
    <material name="silver">
      <color rgba="1 0 0 1"/>
    </material>
  </visual>
  <collision>
    <origin rpy="0 0 0" xyz="-0.24741 0.540257 -0.0"/>
    <geometry>
      <mesh filename="package://myworkcell_support/urdf/mm_stl/Component2_1.stl" scale="0.001 0.001 0.001"/>
    </geometry>
  </collision>
</link>
<link name="Component3_1">
  <inertial>
    <origin rpy="0 0 0" xyz="0.04309099999999999 0.045145 -0.009279"/>
    <mass value="11.720525"/>
    <inertia ixx="0.066203" ixy="-0.001802" ixz="-0.018723" iyy="0.032762" iyz="0.025571" izz="0.049258"/>
  </inertial>
  <visual>
    <origin rpy="0 0 0" xyz="-0.1535 0.080257 -0.0"/>
    <geometry>
      <mesh filename="package://myworkcell_support/urdf/mm_stl/Component3_1.stl" scale="0.001 0.001 0.001"/>
    </geometry>
    <material name="silver">
      <color rgba="1 0 0 1"/>
    </material>
  </visual>
  <collision>
    <origin rpy="0 0 0" xyz="-0.1535 0.080257 -0.0"/>
    <geometry>
      <mesh filename="package://myworkcell_support/urdf/mm_stl/Component3_1.stl" scale="0.001 0.001 0.001"/>
    </geometry>
  </collision>
</link>
<link name="Component4_1">
  <inertial>
    <origin rpy="0 0 0" xyz="0.013224999999999987 -8.999999999998592e-06 0.29447599999999996"/>
    <mass value="3.928337"/>
    <inertia ixx="0.176253" ixy="-1e-06" ixz="0.227942" iyy="0.179313" iyz="-0.237628" izz="0.004509"/>
  </inertial>
  <visual>
    <origin rpy="0 0 0" xyz="-0.2 -0.025743 -0.015"/>
    <geometry>
      <mesh filename="package://myworkcell_support/urdf/mm_stl/Component4_1.stl" scale="0.001 0.001 0.001"/>
    </geometry>
    <material name="silver">
      <color rgba="1 0 0 1"/>
    </material>
  </visual>
  <collision>
    <origin rpy="0 0 0" xyz="-0.2 -0.025743 -0.015"/>
    <geometry>
      <mesh filename="package://myworkcell_support/urdf/mm_stl/Component4_1.stl" scale="0.001 0.001 0.001"/>
    </geometry>
  </collision>
</link>
<link name="Component5_1">
  <inertial>
    <origin rpy="0 0 0" xyz="-0.011390000000000011 1.2000000000001593e-05 0.00292199999999998"/>
    <mass value="2.858848"/>
    <inertia ixx="0.003957" ixy="1e-06" ixz="0.175233" iyy="0.006606" iyz="-0.176006" izz="0.004148"/>
  </inertial>
  <visual>
    <origin rpy="0 0 0" xyz="-0.16 -0.025743 -0.496"/>
    <geometry>
      <mesh filename="package://myworkcell_support/urdf/mm_stl/Component5_1.stl" scale="0.001 0.001 0.001"/>
    </geometry>
    <material name="silver">
      <color rgba="1 0 0 1"/>
    </material>
  </visual>
  <collision>
    <origin rpy="0 0 0" xyz="-0.16 -0.025743 -0.496"/>
    <geometry>
      <mesh filename="package://myworkcell_support/urdf/mm_stl/Component5_1.stl" scale="0.001 0.001 0.001"/>
    </geometry>
  </collision>
</link>
<link name="Component6_1">
  <inertial>
    <origin rpy="0 0 0" xyz="0.0 0.0 0.007258999999999904"/>
    <mass value="0.340558"/>
    <inertia ixx="9e-05" ixy="0.0" ixz="0.032952" iyy="9e-05" iyz="-0.032952" izz="0.000152"/>
  </inertial>
  <visual>
    <origin rpy="0 0 0" xyz="-0.2 -0.025743 -0.548"/>
    <geometry>
      <mesh filename="package://myworkcell_support/urdf/mm_stl/Component6_1.stl" scale="0.001 0.001 0.001"/>
    </geometry>
    <material name="silver">
      <color rgba="1 0 0 1"/>
    </material>
  </visual>
  <collision>
    <origin rpy="0 0 0" xyz="-0.2 -0.025743 -0.548"/>
    <geometry>
      <mesh filename="package://myworkcell_support/urdf/mm_stl/Component6_1.stl" scale="0.001 0.001 0.001"/>
    </geometry>
  </collision>
</link>
<link name="Component1_1">
  <inertial>
    <origin rpy="0 0 0" xyz="0.030920999999999976 0.07909600000000006 -0.028116"/>
    <mass value="17.668777"/>
    <inertia ixx="0.118243" ixy="-0.027969" ixz="-0.412873" iyy="0.129097" iyz="0.405721" izz="0.132326"/>
  </inertial>
  <visual>
    <origin rpy="0 0 0" xyz="-0.2 0.691257 0.0"/>
    <geometry>
      <mesh filename="package://myworkcell_support/urdf/mm_stl/Component1_1.stl" scale="0.001 0.001 0.001"/>
    </geometry>
    <material name="silver">
      <color rgba="1 0 0 1"/>
    </material>
  </visual>
  <collision>
    <origin rpy="0 0 0" xyz="-0.2 0.691257 0.0"/>
    <geometry>
      <mesh filename="package://myworkcell_support/urdf/mm_stl/Component1_1.stl" scale="0.001 0.001 0.001"/>
    </geometry>
  </collision>
</link>
<joint name="Rev1" type="continuous">
  <origin rpy="0 0 0" xyz="0.04741 0.151 0.0"/>
  <parent link="Component1_1"/>
  <child link="Component2_1"/>
  <axis xyz="0.01 -0.0 -0.0"/>
  <limit effort="30" velocity="1.0" lower="-2" upper="1" />
</joint>
<transmission name="Rev1_tran">
  <type>transmission_interface/SimpleTransmission</type>
  <joint name="Rev1">
    <hardwareInterface>PositionJointInterface</hardwareInterface>
  </joint>
  <actuator name="Rev1_actr">
    <hardwareInterface>PositionJointInterface</hardwareInterface>
    <mechanicalReduction>1</mechanicalReduction>
  </actuator>
</transmission>
<joint name="Rev2" type="continuous">
  <origin rpy="0 0 0" xyz="-0.09391 0.46 0.0"/>
  <parent link="Component2_1"/>
  <child link="Component3_1"/>
  <axis xyz="-0.01 0.0 -0.0"/>
</joint>
<transmission name="Rev2_tran">
  <type>transmission_interface/SimpleTransmission</type>
  <joint name="Rev2">
    <hardwareInterface>PositionJointInterface</hardwareInterface>
  </joint>
  <actuator name="Rev2_actr">
    <hardwareInterface>PositionJointInterface</hardwareInterface>
    <mechanicalReduction>1</mechanicalReduction>
  </actuator>
</transmission>
<joint name="Rev3" type="continuous">
  <origin rpy="0 0 0" xyz="0.0465 0.106 0.015"/>
  <parent link="Component3_1"/>
  <child link="Component4_1"/>
  <axis xyz="-0.0 -0.0 0.01"/>
</joint>
<transmission name="Rev3_tran">
  <type>transmission_interface/SimpleTransmission</type>
  <joint name="Rev3">
    <hardwareInterface>PositionJointInterface</hardwareInterface>
  </joint>
  <actuator name="Rev3_actr">
    <hardwareInterface>PositionJointInterface</hardwareInterface>
    <mechanicalReduction>1</mechanicalReduction>
  </actuator>
</transmission>
<joint name="Rev4" type="continuous">
  <origin rpy="0 0 0" xyz="-0.04 0.0 0.481"/>
  <parent link="Component4_1"/>
  <child link="Component5_1"/>
  <axis xyz="-0.01 0.0 0.0"/>
</joint>
<transmission name="Rev4_tran">
  <type>transmission_interface/SimpleTransmission</type>
  <joint name="Rev4">
    <hardwareInterface>PositionJointInterface</hardwareInterface>
  </joint>
  <actuator name="Rev4_actr">
    <hardwareInterface>PositionJointInterface</hardwareInterface>
    <mechanicalReduction>1</mechanicalReduction>
  </actuator>
</transmission>
<joint name="Rev5" type="continuous">
  <origin rpy="0 0 0" xyz="0.04 0.0 0.052"/>
  <parent link="Component5_1"/>
  <child link="Component6_1"/>
  <axis xyz="0.0 -0.0 0.01"/>
</joint>
<transmission name="Rev5_tran">
  <type>transmission_interface/SimpleTransmission</type>
  <joint name="Rev5">
    <hardwareInterface>PositionJointInterface</hardwareInterface>
  </joint>
  <actuator name="Rev5_actr">
    <hardwareInterface>PositionJointInterface</hardwareInterface>
    <mechanicalReduction>1</mechanicalReduction>
  </actuator>
</transmission>
<joint name="Rev6" type="continuous">
  <origin rpy="0 0 0" xyz="0.2 -0.691257 0.0"/>
  <parent link="base_link"/>
  <child link="Component1_1"/>
  <axis xyz="0.0 0.01 0.0"/>
</joint>
<transmission name="Rev6_tran">
  <type>transmission_interface/SimpleTransmission</type>
  <joint name="Rev6">
    <hardwareInterface>PositionJointInterface</hardwareInterface>
  </joint>
  <actuator name="Rev6_actr">
    <hardwareInterface>PositionJointInterface</hardwareInterface>
    <mechanicalReduction>1</mechanicalReduction>
  </actuator>
</transmission>
<gazebo>
  <plugin filename="libgazebo_ros_control.so" name="control"/>
</gazebo>
</xacro:macro>
</robot>
